2025-08-20 11:46:39 <======> ERROR <======> Authentication failed
Traceback (most recent call last):
  File "/app/Routes/ChatAuthRoutes.py", line 29, in login
    raise ValueError("Authentication failed")
ValueError: Authentication failed


****************************************************************************************************

2025-08-20 12:48:11 <======> ERROR <======> Authentication failed
Traceback (most recent call last):
  File "/app/Routes/ChatAuthRoutes.py", line 29, in login
    raise ValueError("Authentication failed")
ValueError: Authentication failed


****************************************************************************************************

